Workbook

Sheet 5YearBreakeven
A1: observation_date | B1: T5YIE | C1: Column1
A2: 37746 | B2: 1.5 | C2: =DATE(YEAR(A2),MONTH(A2),1) -> 37742
A3: 37747 | B3: 1.42 | C3: =DATE(YEAR(A3),MONTH(A3),1) -> 37742
A4: 37748 | B4: 1.38 | C4: =DATE(YEAR(A4),MONTH(A4),1) -> 37742
A5: 37749 | B5: 1.34 | C5: =DATE(YEAR(A5),MONTH(A5),1) -> 37742
A6: 37750 | B6: 1.4 | C6: =DATE(YEAR(A6),MONTH(A6),1) -> 37742
A7: 37753 | B7: 1.37 | C7: =DATE(YEAR(A7),MONTH(A7),1) -> 37742
A8: 37754 | B8: 1.39 | C8: =DATE(YEAR(A8),MONTH(A8),1) -> 37742
A9: 37755 | B9: 1.32 | C9: =DATE(YEAR(A9),MONTH(A9),1) -> 37742
A10: 37756 | B10: 1.39 | C10: =DATE(YEAR(A10),MONTH(A10),1) -> 37742
A11: 37757 | B11: 1.31 | C11: =DATE(YEAR(A11),MONTH(A11),1) -> 37742
A12: 37760 | B12: 1.34 | C12: =DATE(YEAR(A12),MONTH(A12),1) -> 37742
A13: 37761 | B13: 1.35 | C13: =DATE(YEAR(A13),MONTH(A13),1) -> 37742
... A16: 37764 | B16: 1.31 | C16: =DATE(YEAR(A16),MONTH(A16),1) -> 37742
A17: 37767 | C17: =DATE(YEAR(A17),MONTH(A17),1) -> 37742
A18: 37768 | B18: 1.25 | C18: =DATE(YEAR(A18),MONTH(A18),1) -> 37742
A19: 37769 | B19: 1.23 | C19: =DATE(YEAR(A19),MONTH(A19),1) -> 37742
A20: 37770 | B20: 1.23 | C20: =DATE(YEAR(A20),MONTH(A20),1) -> 37742
A21: 37771 | B21: 1.26 | C21: =DATE(YEAR(A21),MONTH(A21),1) -> 37742
A22: 37774 | B22: 1.29 | C22: =DATE(YEAR(A22),MONTH(A22),1) -> 37773
A23: 37775 | B23: 1.25 | C23: =DATE(YEAR(A23),MONTH(A23),1) -> 37773
A24: 37776 | B24: 1.25 | C24: =DATE(YEAR(A24),MONTH(A24),1) -> 37773
A25: 37777 | B25: 1.31 | C25: =DATE(YEAR(A25),MONTH(A25),1) -> 37773
A26: 37778 | B26: 1.33 | C26: =DATE(YEAR(A26),MONTH(A26),1) -> 37773
A27: 37781 | B27: 1.32 | C27: =DATE(YEAR(A27),MONTH(A27),1) -> 37773
A28: 37782 | B28: 1.31 | C28: =DATE(YEAR(A28),MONTH(A28),1) -> 37773
A29: 37783 | B29: 1.36 | C29: =DATE(YEAR(A29),MONTH(A29),1) -> 37773
... A45: 37805 | B45: 1.44 | C45: =DATE(YEAR(A45),MONTH(A45),1) -> 37803
A46: 37806 | C46: =DATE(YEAR(A46),MONTH(A46),1) -> 37803
A47: 37809 | B47: 1.44 | C47: =DATE(YEAR(A47),MONTH(A47),1) -> 37803
A48: 37810 | B48: 1.41 | C48: =DATE(YEAR(A48),MONTH(A48),1) -> 37803
A49: 37811 | B49: 1.46 | C49: =DATE(YEAR(A49),MONTH(A49),1) -> 37803
A50: 37812 | B50: 1.45 | C50: =DATE(YEAR(A50),MONTH(A50),1) -> 37803
A51: 37813 | B51: 1.42 | C51: =DATE(YEAR(A51),MONTH(A51),1) -> 37803
A52: 37816 | B52: 1.47 | C52: =DATE(YEAR(A52),MONTH(A52),1) -> 37803
A53: 37817 | B53: 1.53 | C53: =DATE(YEAR(A53),MONTH(A53),1) -> 37803
A54: 37818 | B54: 1.56 | C54: =DATE(YEAR(A54),MONTH(A54),1) -> 37803
A55: 37819 | B55: 1.57 | C55: =DATE(YEAR(A55),MONTH(A55),1) -> 37803
A56: 37820 | B56: 1.65 | C56: =DATE(YEAR(A56),MONTH(A56),1) -> 37803
A57: 37823 | B57: 1.63 | C57: =DATE(YEAR(A57),MONTH(A57),1) -> 37803
...

Sheet FEDFUNDS
A1: observation_date | B1: FEDFUNDS
A2: 19906 | B2: 0.8
A3: 19937 | B3: 1.22
A4: 19968 | B4: 1.07
A5: 19998 | B5: 0.85
A6: 20029 | B6: 0.83
A7: 20059 | B7: 1.28
A8: 20090 | B8: 1.39
A9: 20121 | B9: 1.29
A10: 20149 | B10: 1.35
A11: 20180 | B11: 1.43
A12: 20210 | B12: 1.43
A13: 20241 | B13: 1.64
... A861: 46054 | B861: 3.64

Sheet Raw Data
A1: Date | B1: CPI | C1: CPI MoM | D1: CPI YoY | F1: observation_date | G1: CPILFESL | I1: observation_date | J1: PPIACO | L1: observation_date | M1: FEDFUNDS
A2: 17168 | B2: 21.48 | F2: 20821 | G2: 28.5 | I2: 4750 | J2: 12.1 | L2: 19906 | M2: 0.8
A3: 17199 | B3: 21.62 | F3: 20852 | G3: 28.6 | I3: 4781 | J3: 12 | L3: 19937 | M3: 1.22
A4: 17227 | B4: 22 | F4: 20880 | G4: 28.7 | I4: 4809 | J4: 12 | L4: 19968 | M4: 1.07
A5: 17258 | B5: 22 | F5: 20911 | G5: 28.8 | I5: 4840 | J5: 12 | L5: 19998 | M5: 0.85
A6: 17288 | B6: 21.95 | F6: 20941 | G6: 28.8 | I6: 4870 | J6: 11.9 | L6: 20029 | M6: 0.83
A7: 17319 | B7: 22.08 | F7: 20972 | G7: 28.9 | I7: 4901 | J7: 11.9 | L7: 20059 | M7: 1.28
A8: 17349 | B8: 22.23 | F8: 21002 | G8: 29 | I8: 4931 | J8: 12 | L8: 20090 | M8: 1.39
A9: 17380 | B9: 22.4 | F9: 21033 | G9: 29 | I9: 4962 | J9: 12 | L9: 20121 | M9: 1.29
A10: 17411 | B10: 22.84 | F10: 21064 | G10: 29.1 | I10: 4993 | J10: 12.2 | L10: 20149 | M10: 1.35
A11: 17441 | B11: 22.91 | F11: 21094 | G11: 29.2 | I11: 5023 | J11: 12.2 | L11: 20180 | M11: 1.43
A12: 17472 | B12: 23.06 | F12: 21125 | G12: 29.3 | I12: 5054 | J12: 12.1 | L12: 20210 | M12: 1.43
A13: 17502 | B13: 23.41 | F13: 21155 | G13: 29.3 | I13: 5084 | J13: 11.9 | L13: 20241 | M13: 1.64
... A697: 38322 | B697: 191.7 | F697: 41974 | G697: 239.584 | I697: 25903 | J697: 37.1 | L697: 41061 | M697: 0.16
A698: 38353 | B698: 191.6 | C698: =(B3 / B2) - 1 -> 0.0065176909 | F698: 42005 | G698: 239.811 | I698: 25934 | J698: 37.3 | L698: 41091 | M698: 0.16
A699: 38384 | B699: 192.4 | C699: =(B4 / B3) - 1 -> 0.017576318 | F699: 42036 | G699: 240.172 | I699: 25965 | J699: 37.7 | L699: 41122 | M699: 0.13
A700: 38412 | B700: 193.1 | C700: =(B5 / B4) - 1 -> 0 | F700: 42064 | G700: 240.755 | I700: 25993 | J700: 37.8 | L700: 41153 | M700: 0.14
A701: 38443 | B701: 193.7 | C701: =(B6 / B5) - 1 -> -0.0022727273 | F701: 42095 | G701: 241.346 | I701: 26024 | J701: 37.9 | L701: 41183 | M701: 0.16
A702: 38473 | B702: 193.6 | C702: =(B7 / B6) - 1 -> 0.0059225513 | F702: 42125 | G702: 241.688 | I702: 26054 | J702: 38.1 | L702: 41214 | M702: 0.16
A703: 38504 | B703: 193.7 | C703: =(B8 / B7) - 1 -> 0.0067934783 | F703: 42156 | G703: 242.064 | I703: 26085 | J703: 38.2 | L703: 41244 | M703: 0.16
A704: 38534 | B704: 194.9 | C704: =(B9 / B8) - 1 -> 0.0076473234 | F704: 42186 | G704: 242.565 | I704: 26115 | J704: 38.3 | L704: 41275 | M704: 0.14
A705: 38565 | B705: 196.1 | C705: =(B10 / B9) - 1 -> 0.019642857 | F705: 42217 | G705: 242.817 | I705: 26146 | J705: 38.5 | L705: 41306 | M705: 0.15
A706: 38596 | B706: 198.8 | C706: =(B11 / B10) - 1 -> 0.0030647986 | F706: 42248 | G706: 243.316 | I706: 26177 | J706: 38.3 | L706: 41334 | M706: 0.14
A707: 38626 | B707: 199.1 | C707: =(B12 / B11) - 1 -> 0.0065473592 | F707: 42278 | G707: 243.768 | I707: 26207 | J707: 38.3 | L707: 41365 | M707: 0.15
A708: 38657 | B708: 198.1 | C708: =(B13 / B12) - 1 -> 0.015177797 | F708: 42309 | G708: 244.241 | I708: 26238 | J708: 38.3 | L708: 41395 | M708: 0.11
A709: 38687 | B709: 198.1 | C709: =(B14 / B13) - 1 -> 0.011533533 | F709: 42339 | G709: 244.547 | I709: 26268 | J709: 38.6 | L709: 41426 | M709: 0.09
... A711: 38749 | B711: 199.4 | C711: =(B16 / B15) - 1 -> -0.007182087 | F711: 42401 | G711: 245.51 | I711: 26330 | J711: 39.2 | L711: 41487 | M711: 0.08
A712: 38777 | B712: 199.7 | C712: =(B17 / B16) - 1 -> 0.013617021 | D712: =(B14 / B2) - 1 -> 0.10242086 | F712: 42430 | G712: 245.913 | I712: 26359 | J712: 39.2 | L712: 41518 | M712: 0.08
A713: 38808 | B713: 200.7 | C713: =(B18 / B17) - 1 -> 0.0079764903 | D713: =(B15 / B3) - 1 -> 0.094819611 | F713: 42461 | G713: 246.551 | I713: 26390 | J713: 39.3 | L713: 41548 | M713: 0.09
A714: 38838 | B714: 201.3 | C714: =(B19 / B18) - 1 -> 0.0058309038 | D714: =(B16 / B4) - 1 -> 0.068181818 | F714: 42491 | G714: 247.137 | I714: 26420 | J714: 39.5 | L714: 41579 | M714: 0.08
A715: 38869 | B715: 201.8 | C715: =(B20 / B19) - 1 -> 0.010351967 | D715: =(B17 / B5) - 1 -> 0.082727273 | F715: 42522 | G715: 247.54 | I715: 26451 | J715: 39.7 | L715: 41609 | M715: 0.09
A716: 38899 | B716: 202.9 | C716: =(B21 / B20) - 1 -> 0.0012295082 | D716: =(B18 / B6) - 1 -> 0.093849658 | F716: 42552 | G716: 247.829 | I716: 26481 | J716: 40 | L716: 41640 | M716: 0.07
A717: 38930 | B717: 203.8 | C717: =(B22 / B21) - 1 -> -0.0028653295 | D717: =(B19 / B7) - 1 -> 0.09375 | F717: 42583 | G717: 248.423 | I717: 26512 | J717: 40.1 | L717: 41671 | M717: 0.07
A718: 38961 | B718: 202.8 | C718: =(B23 / B22) - 1 -> -0.0020525452 | D718: =(B20 / B8) - 1 -> 0.097615834 | F718: 42614 | G718: 248.842 | I718: 26543 | J718: 40.2 | L718: 41699 | M718: 0.08
A719: 38991 | B719: 201.9 | C719: =(B24 / B23) - 1 -> -0.0061703003 | D719: =(B21 / B9) - 1 -> 0.090625 | F719: 42644 | G719: 249.142 | I719: 26573 | J719: 40.1 | L719: 41730 | M719: 0.09
A720: 39022 | B720: 202 | C720: =(B25 / B24) - 1 -> -0.0045529801 | D720: =(B22 / B10) - 1 -> 0.066549912 | F720: 42675 | G720: 249.481 | I720: 26604 | J720: 40.3 | L720: 41760 | M720: 0.09
A721: 39052 | B721: 203.1 | C721: =(B26 / B25) - 1 -> -0.0016632017 | D721: =(B23 / B11) - 1 -> 0.061108686 | F721: 42705 | G721: 249.92 | I721: 26634 | J721: 41.1 | L721: 41791 | M721: 0.1
A722: 39083 | B722: 203.437 | C722: =(B27 / B26) - 1 -> -0.0041649313 | D722: =(B24 / B12) - 1 -> 0.047701648 | F722: 42736 | G722: 250.467 | I722: 26665 | J722: 41.6 | L722: 41821 | M722: 0.09
A723: 39114 | B723: 204.226 | C723: =(B28 / B27) - 1 -> 0 | D723: =(B25 / B13) - 1 -> 0.027338744 | F723: 42767 | G723: 250.998 | I723: 26696 | J723: 42.4 | L723: 41852 | M723: 0.09
... A826: 42248 | B826: 237.498 | C826: =(B131 / B130) - 1 -> 0 | D826: =(B128 / B116) - 1 -> 0.032979113 | F826: 45901 | G826: 330.418 | I826: 29830 | J826: 98.8 | L826: 44986 | M826: 4.65
...

Sheet Model Data
A1: Date | B1: CPI | C1: CPI MoM | D1: CPI YoY | E1: Core CPI | F1: Core CPI YoY | G1: PPI | H1: PPI YoY | I1: 5Y Breakeven | J1: Federal Funds
A2: 38353 | B2: =VLOOKUP(A2, 'Raw Data'!A:B, 2, FALSE) -> 191.6 | C2: =(B3 / B2) - 1 -> 0.0041753653 | D2: =B14 / B2 - 1 -> 0.040187891 | E2: =VLOOKUP(A2, 'Raw Data'!F:G, 2, FALSE) -> 199 | F2: =E14/E2 - 1 -> 0.021105528 | G2: =VLOOKUP(A2,'Raw Data'!I:J,2,FALSE) -> 150.9 | H2: =G14 / G2 - 1 -> 0.08880053
A3: 38384 | B3: =VLOOKUP(A3, 'Raw Data'!A:B, 2, FALSE) -> 192.4 | C3: =(B4 / B3) - 1 -> 0.0036382536 | D3: =B15 / B3 - 1 -> 0.036382536 | E3: =VLOOKUP(A3, 'Raw Data'!F:G, 2, FALSE) -> 199.4 | F3: =E15/E3 - 1 -> 0.02106319 | G3: =VLOOKUP(A3,'Raw Data'!I:J,2,FALSE) -> 151.6 | H3: =G15 / G3 - 1 -> 0.067282322
A4: 38412 | B4: =VLOOKUP(A4, 'Raw Data'!A:B, 2, FALSE) -> 193.1 | C4: =(B5 / B4) - 1 -> 0.0031071983 | D4: =B16 / B4 - 1 -> 0.034179182 | E4: =VLOOKUP(A4, 'Raw Data'!F:G, 2, FALSE) -> 200.1 | F4: =E16/E4 - 1 -> 0.020989505 | G4: =VLOOKUP(A4,'Raw Data'!I:J,2,FALSE) -> 153.7 | H4: =G16 / G4 - 1 -> 0.055302537
A5: 38443 | B5: =VLOOKUP(A5, 'Raw Data'!A:B, 2, FALSE) -> 193.7 | C5: =(B6 / B5) - 1 -> -0.00051626226 | D5: =B17 / B5 - 1 -> 0.036138358 | E5: =VLOOKUP(A5, 'Raw Data'!F:G, 2, FALSE) -> 200.2 | F5: =E17/E5 - 1 -> 0.022977023 | G5: =VLOOKUP(A5,'Raw Data'!I:J,2,FALSE) -> 155 | H5: =G17 / G5 - 1 -> 0.06
A6: 38473 | B6: =VLOOKUP(A6, 'Raw Data'!A:B, 2, FALSE) -> 193.6 | C6: =(B7 / B6) - 1 -> 0.00051652893 | D6: =B18 / B6 - 1 -> 0.039772727 | E6: =VLOOKUP(A6, 'Raw Data'!F:G, 2, FALSE) -> 200.5 | F6: =E18/E6 - 1 -> 0.024438903 | G6: =VLOOKUP(A6,'Raw Data'!I:J,2,FALSE) -> 154.3 | H6: =G18 / G6 - 1 -> 0.074530136
A7: 38504 | B7: =VLOOKUP(A7, 'Raw Data'!A:B, 2, FALSE) -> 193.7 | C7: =(B8 / B7) - 1 -> 0.0061951471 | D7: =B19 / B7 - 1 -> 0.041817243 | E7: =VLOOKUP(A7, 'Raw Data'!F:G, 2, FALSE) -> 200.6 | F7: =E19/E7 - 1 -> 0.026420738 | G7: =VLOOKUP(A7,'Raw Data'!I:J,2,FALSE) -> 154.3 | H7: =G19 / G7 - 1 -> 0.076474401
A8: 38534 | B8: =VLOOKUP(A8, 'Raw Data'!A:B, 2, FALSE) -> 194.9 | C8: =(B9 / B8) - 1 -> 0.0061570036 | D8: =B20 / B8 - 1 -> 0.041046691 | E8: =VLOOKUP(A8, 'Raw Data'!F:G, 2, FALSE) -> 200.9 | F8: =E20/E8 - 1 -> 0.026879044 | G8: =VLOOKUP(A8,'Raw Data'!I:J,2,FALSE) -> 156.3 | H8: =G20 / G8 - 1 -> 0.067178503
A9: 38565 | B9: =VLOOKUP(A9, 'Raw Data'!A:B, 2, FALSE) -> 196.1 | C9: =(B10 / B9) - 1 -> 0.013768485 | D9: =B21 / B9 - 1 -> 0.039265681 | E9: =VLOOKUP(A9, 'Raw Data'!F:G, 2, FALSE) -> 201.1 | F9: =E21/E9 - 1 -> 0.028344107 | G9: =VLOOKUP(A9,'Raw Data'!I:J,2,FALSE) -> 157.6 | H9: =G21 / G9 - 1 -> 0.06535533
A10: 38596 | B10: =VLOOKUP(A10, 'Raw Data'!A:B, 2, FALSE) -> 198.8 | C10: =(B11 / B10) - 1 -> 0.0015090543 | D10: =B22 / B10 - 1 -> 0.020120724 | E10: =VLOOKUP(A10, 'Raw Data'!F:G, 2, FALSE) -> 201.3 | F10: =E22/E10 - 1 -> 0.029309488 | G10: =VLOOKUP(A10,'Raw Data'!I:J,2,FALSE) -> 162.2 | H10: =G22 / G10 - 1 -> 0.01972873
A11: 38626 | B11: =VLOOKUP(A11, 'Raw Data'!A:B, 2, FALSE) -> 199.1 | C11: =(B12 / B11) - 1 -> -0.0050226017 | D11: =B23 / B11 - 1 -> 0.014063285 | E11: =VLOOKUP(A11, 'Raw Data'!F:G, 2, FALSE) -> 202 | F11: =E23/E11 - 1 -> 0.027722772 | G11: =VLOOKUP(A11,'Raw Data'!I:J,2,FALSE) -> 166.2 | H11: =G23 / G11 - 1 -> -0.024067389
A12: 38657 | B12: =VLOOKUP(A12, 'Raw Data'!A:B, 2, FALSE) -> 198.1 | C12: =(B13 / B12) - 1 -> 0 | D12: =B24 / B12 - 1 -> 0.019687027 | E12: =VLOOKUP(A12, 'Raw Data'!F:G, 2, FALSE) -> 202.5 | F12: =E24/E12 - 1 -> 0.02617284 | G12: =VLOOKUP(A12,'Raw Data'!I:J,2,FALSE) -> 163.7 | H12: =G24 / G12 - 1 -> 0.0054978619
A13: 38687 | B13: =VLOOKUP(A13, 'Raw Data'!A:B, 2, FALSE) -> 198.1 | C13: =(B14 / B13) - 1 -> 0.0060575467 | D13: =B25 / B13 - 1 -> 0.025239778 | E13: =VLOOKUP(A13, 'Raw Data'!F:G, 2, FALSE) -> 202.8 | F13: =E25/E13 - 1 -> 0.026134122 | G13: =VLOOKUP(A13,'Raw Data'!I:J,2,FALSE) -> 163 | H13: =G25 / G13 - 1 -> 0.01595092
... A255: 46054 | B255: =VLOOKUP(A255, 'Raw Data'!A:B, 2, FALSE) -> 327.46 | C255: =(B256 / B255) - 1 -> -1 | D255: =B267 / B255 - 1 -> -1 | E255: =VLOOKUP(A255, 'Raw Data'!F:G, 2, FALSE) -> 333.512 | F255: =E267/E255 - 1 -> -1 | G255: =VLOOKUP(A255,'Raw Data'!I:J,2,FALSE) -> 267.848 | H255: =G267 / G255 - 1 -> -1

Sheet Notes Sources
A1: All Sources | B1: CPI | C1: Core CPI | D1: PPI | E1: PPI YoY | F1: 5Y Breakeven | G1: Federal Funds
B2: https://fred.stlouisfed.org/series/CPIAUCSL?utm_source=chatgpt.com | C2: https://fred.stlouisfed.org/series/CPILFESL?utm_source=chatgpt.com | E2: https://fred.stlouisfed.org/series/PPIACO?utm_source=chatgpt.com | F2: https://fred.stlouisfed.org/series/T5YIE?utm_source=chatgpt.com
G3: https://fred.stlouisfed.org/series/FEDFUNDS?utm_source=chatgpt.com
